<mujoco model="hopper">
  <compiler inertiafromgeom="true" angle="degree" coordinate="global" />
  <default>
    <joint limited='true' damping='1' armature='1' />
    <geom contype='1' conaffinity='1' condim='1' rgba='0.8 0.6 .4 1' margin="0.001" solref=".02 1" solimp=".8 .8 .01" material="geom" />
    <motor ctrlrange='-.4 .4' ctrllimited='true' />
  </default>
  <option timestep="0.02" integrator="RK4" />
  <asset>
    <texture type="skybox" builtin="gradient" width="100" height="100" rgb1="1 1 1" rgb2="0 0 0" />
    <texture name="texgeom" type="cube" builtin="flat" mark="cross" width="127" height="1278" rgb1="0.8 0.6 0.4" rgb2="0.8 0.6 0.4" markrgb="1 1 1" random="0.01" />
    <texture name="texplane" type="2d" builtin="checker" rgb1="0 0 0" rgb2="0.8 0.8 0.8" width="100" height="100" />
    <material name='MatPlane' texture="texplane" shininess="1" texrepeat="60 60" specular="1"  reflectance="0.5" />
    <material name='geom' texture="texgeom" texuniform="true" />
  </asset>
  <worldbody>
    <light directional="true" cutoff="100" exponent="1" diffuse="1 1 1" specular=".1 .1 .1" pos="0 0 1.3" dir="-0 0 -1.3" />
    <geom name='floor' material="MatPlane" pos='0 0 0' size='40 40 40' type='plane' conaffinity='1' rgba='0.8 0.9 0.8 1' condim='3' />
    <body name="torso" pos="0 0 1.25">
      <joint name='rootz' type='slide' axis='0 0 1' pos='0 0 0' limited='false' damping='0' armature='0' stiffness='0' ref="1.25" />
      <joint name='rootx' type='slide' axis='1 0 0' pos='0 0 0' limited='false' damping='0' armature='0' stiffness='0' />
      <joint name='rooty' type='hinge' axis='0 1 0' pos='0 0 1.25' limited='false' damping='0' armature='0' stiffness='0' />
      <geom name="torso_geom" type="capsule" fromto="0 0 1.45 0 0 1.05" size="0.05" friction="0.9" />
      <body name="thigh" pos="0 0 1.05">
        <joint name="thigh_joint" type="hinge" pos="0 0 1.05" axis="0 -1 0" range="-150 0" />
        <geom name="thigh_geom" type="capsule" fromto="0 0 1.05 0 0 0.6" size="0.05" friction="0.9" />
        <body name="leg" pos="0 0 0.35">
          <joint name="leg_joint" type="hinge" pos="0 0 0.6" axis="0 -1 0" range="-150 0" />
          <geom name="leg_geom" type="capsule" fromto="0 0 0.6 0 0 0.1" size="0.04" friction="0.9" />
          <body name="foot" pos="0.13/2 0 0.1">
            <joint name="foot_joint" type="hinge" pos="0 0 0.1" axis="0 -1 0" range="-45 45" />
            <geom name="foot_geom" type="capsule" fromto="-0.13 0 0.1 0.26 0 0.1" size="0.06" friction="2.0" />
          </body>
        </body>
      </body>
    </body>
  </worldbody>
  <actuator>
    <!-- <motor joint="torso_joint" ctrlrange="-100.0 100.0" isctrllimited="true"/> -->
    <motor joint="thigh_joint" ctrlrange="-200.0 200.0" ctrllimited="true" />
    <motor joint="leg_joint" ctrlrange="-200.0 200.0" ctrllimited="true" />
    <motor joint="foot_joint" ctrlrange="-200.0 200.0" ctrllimited="true" />
    <!-- <motor joint="finger2_rot" ctrlrange="-20.0 20.0" isctrllimited="true"/> -->
  </actuator>
</mujoco>
